<?xml version="1.0"?>
<robot xmlns:xacro="http://www.ros.org/wiki/xacro" >

    <xacro:include filename="inertial_macros.xacro"/>

    <material name="white">
        <color rgba="1 1 1 1" />
    </material>

    <material name="orange">
        <color rgba="1 0.3 0.1 1"/>
    </material>

    <material name="blue">
        <color rgba="0.2 0.2 1 1"/>
    </material>

    <material name="black">
        <color rgba="0 0 0 1"/>
    </material>

    <!-- BASE LINK -->

    <link name="base_link"></link>

    <link name="body">
        <visual>
            <geometry>
                <mesh filename="package://wheelchair_bot/meshes/body.dae" />
            </geometry>
            <origin xyz="0 0 0" rpy="0 0 0" />
        </visual>
        <collision>
            <geometry>
                <mesh filename="package://wheelchair_bot/meshes/body.dae" />
            </geometry>
            <origin xyz="0 0 0" rpy="0 0 0" />
        </collision>
    </link>

    <joint name="body_joint" type="fixed">
        <parent link="base_link"/>
        <child link="body"/>
        <origin xyz="0 0 0.4009"/>
    </joint>

    <!-- LEFT WHEEL LINK -->

    <joint name="left_wheel_joint" type="continuous">
        <parent link="base_link"/>
        <child link="left_wheel"/>
        <origin xyz="0.33 0.29 0.3053" rpy="0 0 0" />
        <axis xyz="1 0 0"/>
    </joint>

    <link name="left_wheel">
        <visual>
            <geometry>
                <mesh filename="package://wheelchair_bot/meshes/wheel.dae" />
            </geometry>
            <origin xyz="0 0.024 -0.009" rpy="0 0 0" />
        </visual>
        <collision>
            <geometry>
                <mesh filename="package://wheelchair_bot/meshes/wheel.dae" />
            </geometry>
            <origin xyz="0 0.024 -0.009" rpy="0 0 0" />
        </collision>
        <xacro:inertial_cylinder mass="0.1" length="0.04" radius="0.05">
            <origin xyz="0 0 0" rpy="0 0 0"/>
        </xacro:inertial_cylinder>
    </link>

    <!-- RIGHT WHEEL LINK -->

    <joint name="right_wheel_joint" type="continuous">
        <parent link="base_link"/>
        <child link="right_wheel"/>
        <origin xyz="-0.33 0.29 0.3053" rpy="0 0 3.14159" />
        <axis xyz="-1 0 0"/>
    </joint>

    <link name="right_wheel">
        <visual>
            <geometry>
                <mesh filename="package://wheelchair_bot/meshes/wheel.dae" />
            </geometry>
            <origin xyz="0 0.024 -0.009" rpy="0 0 0" />
        </visual>
        <collision>
            <geometry>
                <mesh filename="package://wheelchair_bot/meshes/wheel.dae" />
            </geometry>
            <origin xyz="0 0.024 -0.009" rpy="0 0 0" />
        </collision>
        <xacro:inertial_cylinder mass="0.1" length="0.04" radius="0.05">
            <origin xyz="0 0 0" rpy="0 0 0"/>
        </xacro:inertial_cylinder>
    </link>
    
</robot>